<?xml version="1.0"?>
<robot name="ur5">
    <!-- Base Link -->
    <link name="base_link">
        <visual>
            <geometry>
                <cylinder radius="0.1" length="0.05"/>
            </geometry>
            <material name="blue">
                <color rgba="0 0 1 1"/>
            </material>
        </visual>
        <collision>
            <geometry>
                <cylinder radius="0.1" length="0.05"/>
            </geometry>
        </collision>
        <inertial>
            <mass value="1.0"/>
            <inertia ixx="1.0" ixy="0.0" ixz="0.0" iyy="1.0" iyz="0.0" izz="1.0"/>
        </inertial>
    </link>

    <!-- Shoulder Link -->
    <link name="shoulder_link">
        <visual>
            <geometry>
                <box size="0.1 0.3 0.1"/>
            </geometry>
            <material name="red">
                <color rgba="1 0 0 1"/>
            </material>
        </visual>
        <collision>
            <geometry>
                <box size="0.1 0.3 0.1"/>
            </geometry>
        </collision>
        <inertial>
            <mass value="1.0"/>
            <inertia ixx="1.0" ixy="0.0" ixz="0.0" iyy="1.0" iyz="0.0" izz="1.0"/>
        </inertial>
    </link>

    <!-- Upper Arm Link -->
    <link name="upper_arm_link">
        <visual>
            <geometry>
                <box size="0.1 0.3 0.1"/>
            </geometry>
            <material name="green">
                <color rgba="0 1 0 1"/>
            </material>
        </visual>
        <collision>
            <geometry>
                <box size="0.1 0.3 0.1"/>
            </geometry>
        </collision>
        <inertial>
            <mass value="1.0"/>
            <inertia ixx="1.0" ixy="0.0" ixz="0.0" iyy="1.0" iyz="0.0" izz="1.0"/>
        </inertial>
    </link>

    <!-- Forearm Link -->
    <link name="forearm_link">
        <visual>
            <geometry>
                <box size="0.1 0.3 0.1"/>
            </geometry>
            <material name="yellow">
                <color rgba="1 1 0 1"/>
            </material>
        </visual>
        <collision>
            <geometry>
                <box size="0.1 0.3 0.1"/>
            </geometry>
        </collision>
        <inertial>
            <mass value="1.0"/>
            <inertia ixx="1.0" ixy="0.0" ixz="0.0" iyy="1.0" iyz="0.0" izz="1.0"/>
        </inertial>
    </link>

    <!-- Wrist 1 Link -->
    <link name="wrist_1_link">
        <visual>
            <geometry>
                <box size="0.1 0.15 0.1"/>
            </geometry>
            <material name="purple">
                <color rgba="1 0 1 1"/>
            </material>
        </visual>
        <collision>
            <geometry>
                <box size="0.1 0.15 0.1"/>
            </geometry>
        </collision>
        <inertial>
            <mass value="1.0"/>
            <inertia ixx="1.0" ixy="0.0" ixz="0.0" iyy="1.0" iyz="0.0" izz="1.0"/>
        </inertial>
    </link>

    <!-- Wrist 2 Link -->
    <link name="wrist_2_link">
        <visual>
            <geometry>
                <box size="0.1 0.15 0.1"/>
            </geometry>
            <material name="orange">
                <color rgba="1 0.5 0 1"/>
            </material>
        </visual>
        <collision>
            <geometry>
                <box size="0.1 0.15 0.1"/>
            </geometry>
        </collision>
        <inertial>
            <mass value="1.0"/>
            <inertia ixx="1.0" ixy="0.0" ixz="0.0" iyy="1.0" iyz="0.0" izz="1.0"/>
        </inertial>
    </link>

    <!-- Wrist 3 Link -->
    <link name="wrist_3_link">
        <visual>
            <geometry>
                <box size="0.1 0.1 0.1"/>
            </geometry>
            <material name="white">
                <color rgba="1 1 1 1"/>
            </material>
        </visual>
        <collision>
            <geometry>
                <box size="0.1 0.1 0.1"/>
            </geometry>
        </collision>
        <inertial>
            <mass value="1.0"/>
            <inertia ixx="1.0" ixy="0.0" ixz="0.0" iyy="1.0" iyz="0.0" izz="1.0"/>
        </inertial>
    </link>

    <!-- Joints -->
    <joint name="base_to_shoulder" type="revolute">
        <parent link="base_link"/>
        <child link="shoulder_link"/>
        <axis xyz="0 0 1"/>
        <limit lower="-3.14159" upper="3.14159" effort="100" velocity="1"/>
    </joint>

    <joint name="shoulder_to_upper_arm" type="revolute">
        <parent link="shoulder_link"/>
        <child link="upper_arm_link"/>
        <axis xyz="0 1 0"/>
        <limit lower="-3.14159" upper="3.14159" effort="100" velocity="1"/>
    </joint>

    <joint name="upper_arm_to_forearm" type="revolute">
        <parent link="upper_arm_link"/>
        <child link="forearm_link"/>
        <axis xyz="0 1 0"/>
        <limit lower="-3.14159" upper="3.14159" effort="100" velocity="1"/>
    </joint>

    <joint name="forearm_to_wrist_1" type="revolute">
        <parent link="forearm_link"/>
        <child link="wrist_1_link"/>
        <axis xyz="0 1 0"/>
        <limit lower="-3.14159" upper="3.14159" effort="100" velocity="1"/>
    </joint>

    <joint name="wrist_1_to_wrist_2" type="revolute">
        <parent link="wrist_1_link"/>
        <child link="wrist_2_link"/>
        <axis xyz="0 0 1"/>
        <limit lower="-3.14159" upper="3.14159" effort="100" velocity="1"/>
    </joint>

    <joint name="wrist_2_to_wrist_3" type="revolute">
        <parent link="wrist_2_link"/>
        <child link="wrist_3_link"/>
        <axis xyz="0 1 0"/>
        <limit lower="-3.14159" upper="3.14159" effort="100" velocity="1"/>
    </joint>
</robot>